Workbook

Sheet SummaryStats
A1: Model | B1: Evaluation Metrics
B2: elements_used_pct | C2: element_precision | D2: element_recall | E2: element_f1 | F2: response_relevancy | G2: factual_correctness | H2: semantic_similarity | I2: faithfulness | J2: Total Input Tokens Used
A3: GPT-5.2+Interative Schema Aware RAG | B3: =AVERAGE('GPT5.2_RAG'!N$2:N$30) -> 0.32358415 | C3: =AVERAGE('GPT5.2_RAG'!O$2:O$30) -> 0.72025227 | D3: =AVERAGE('GPT5.2_RAG'!P$2:P$30) -> 0.70429169 | E3: =AVERAGE('GPT5.2_RAG'!Q$2:Q$30) -> 0.68245643 | F3: =AVERAGE('GPT5.2_RAG'!R$2:R$36) -> 0.71130166 | G3: =AVERAGE('GPT5.2_RAG'!S$2:S$36) -> 0.79085714 | H3: =AVERAGE('GPT5.2_RAG'!T$2:T$36) -> 0.84724839 | I3: =AVERAGE('GPT5.2_RAG'!U$2:U$36) -> 0.67705215 | J3: 102365
A4: GPT-5.2+Single Prompt | B4: =AVERAGE('GPT5.2_SnglPrompt'!N$2:N$30) -> 0.012893983 | C4: =AVERAGE('GPT5.2_SnglPrompt'!O$2:O$30) -> 0.4352033 | D4: =AVERAGE('GPT5.2_SnglPrompt'!P$2:P$30) -> 0.71565532 | E4: =AVERAGE('GPT5.2_SnglPrompt'!Q$2:Q$30) -> 0.46723838 | F4: =AVERAGE('GPT5.2_SnglPrompt'!R$2:R$36) -> 0.63984541 | G4: =AVERAGE('GPT5.2_SnglPrompt'!S$2:S$36) -> 0.74542857 | H4: =AVERAGE('GPT5.2_SnglPrompt'!T$2:T$36) -> 0.79887001 | I4: =AVERAGE('GPT5.2_SnglPrompt'!U$2:U$36) -> 0.67501483 | J4: 463090 | K4: =J4/J3 -> 4.5239095
A5: GPT-4.1+Interative Schema Aware RAG | B5: =AVERAGE('GPT4.1_RAG'!N$2:N$30) -> 0.60336093 | C5: =AVERAGE('GPT4.1_RAG'!O$2:O$30) -> 0.68850495 | D5: =AVERAGE('GPT4.1_RAG'!P$2:P$30) -> 0.63506494 | E5: =AVERAGE('GPT4.1_RAG'!Q$2:Q$30) -> 0.64595347 | F5: =AVERAGE('GPT4.1_RAG'!R$2:R$36) -> 0.71832773 | G5: =AVERAGE('GPT4.1_RAG'!S$2:S$36) -> 0.666 | H5: =AVERAGE('GPT4.1_RAG'!T$2:T$36) -> 0.8307224 | I5: =AVERAGE('GPT4.1_RAG'!U$2:U$36) -> 0.73316398 | J5: 75682 | K5: =J6/J5 -> 6.1198171
A6: GPT-4.1+Single Prompt | B6: =AVERAGE('GPT4.1_SnglPrompt'!N$2:N$30) -> 0.010572078 | C6: =AVERAGE('GPT4.1_SnglPrompt'!O$2:O$30) -> 0.54464343 | D6: =AVERAGE('GPT4.1_SnglPrompt'!P$2:P$30) -> 0.74060308 | E6: =AVERAGE('GPT4.1_SnglPrompt'!Q$2:Q$30) -> 0.58708391 | F6: =AVERAGE('GPT4.1_SnglPrompt'!R$2:R$36) -> 0.76242186 | G6: =AVERAGE('GPT4.1_SnglPrompt'!S$2:S$36) -> 0.72971429 | H6: =AVERAGE('GPT4.1_SnglPrompt'!T$2:T$36) -> 0.83033392 | I6: =AVERAGE('GPT4.1_SnglPrompt'!U$2:U$36) -> 0.60861278 | J6: 463160

Sheet GPT5.2_RAG
A1: classification | B1: question | C1: response | D1: expected_answer | E1: elements_included_in_prompt | F1: elements_used | G1: expected_elements | H1: faithfulness_contexts | I1: retrieved_contexts_derived | J1: retrieved_contexts_used_for_faithfulness | K1: canonical_prompt_elements | L1: canonical_used_elements | M1: canonical_expected_elements | N1: elements_used_pct | O1: element_precision | P1: element_recall | Q1: element_f1 | R1: response_relevancy | S1: factual_correctness | T1: semantic_similarity | U1: faithfulness
A2: Entity Only | B2: What/who are the organizational entites which carry out functions? | C2: The organizational entities that carry out functions are Back Office (type: BusinessActor) which carries out Actuarial (type: BusinessFunction), Claims (type: BusinessFunction), Finance (type: BusinessFunction), Investment Management (type: BusinessFunction), and Underwriting (type: BusinessFunction); Bank (type: BusinessActor) which carries out Banking (type: BusinessFunction); Client (type: BusinessActor) which carries out Buying Insurance (type: BusinessFunction), Claims Submission (type: BusinessFunction), and Information Provisioning (type: BusinessFunction); Front Office (type: BusinessActor) which carries out Customer Relations (type: BusinessFunction), Marketing (type: BusinessFunction), and Sales (type: BusinessFunction); and Shared Service Center (type: BusinessActor) which carries out Document Processing (type: BusinessFunction). | D2: The domain consists of the following actors ArchiSurance (type: BusinessActor), Front Office (type: BusinessActor), Back Office (type: BusinessActor), Shared Service Center (type: BusinessActor), Homeowner's Travel Back Office (type: BusinessActor), Legal Expense Back Office (type: BusinessActor), Auto Back Office (type: BusinessActor), Client (type: BusinessActor), Bank (type: BusinessActor), Customer Service (type: BusinessActor), and Business Intelligence Team (type: BusinessActor). | E2: ['Back Office (type: BusinessActor) AssignmentRelationship Actuarial (type: BusinessFunction)', 'Back Office (type: BusinessActor) AssignmentRelationship Claims (type: BusinessFunction)', 'Back Office (type: BusinessActor) AssignmentRelationship Finance (type: BusinessFunction)', 'Back Office (type: BusinessActor) AssignmentRelationship Investment Management (type: BusinessFunction)', 'Back Office (type: BusinessActor) AssignmentRelationship Underwriting (type: BusinessFunction)', 'Bank (type: BusinessActor) AssignmentRelationship Banking (type: BusinessFunction)', 'Client (type: BusinessActor) AssignmentRelationship Buying Insurance (type: BusinessFunction)', 'Client (type: BusinessActor) AssignmentRelationship Claims Submission (type: BusinessFunction)', 'Client (type: BusinessActor) AssignmentRelationship Information Provisioning (type: BusinessFunction)', 'Front Office (type: BusinessActor) AssignmentRelationship Customer Relations (type: BusinessFunction)', 'Front Office (type: BusinessActor) AssignmentRelationship Marketing (type: BusinessFunction)', 'Front Office (type: BusinessActor) AssignmentRelationship Sales (type: BusinessFunction)', 'Shared Service Center (type: BusinessActor) AssignmentRelationship Document Processing (type: BusinessFunction)'] | F2: ['Back Office (type: BusinessActor) AssignmentRelationship Actuarial (type: BusinessFunction)', 'Back Office (type: BusinessActor) AssignmentRelationship Claims (type: BusinessFunction)', 'Back Office (type: BusinessActor) AssignmentRelationship Finance (type: BusinessFunction)', 'Back Office (type: BusinessActor) AssignmentRelationship Investment Management (type: BusinessFunction)', 'Back Office (type: BusinessActor) AssignmentRelationship Underwriting (type: BusinessFunction)', 'Bank (type: BusinessActor) AssignmentRelationship Banking (type: BusinessFunction)', 'Client (type: BusinessActor) AssignmentRelationship Buying Insurance (type: BusinessFunction)', 'Client (type: BusinessActor) AssignmentRelationship Claims Submission (type: BusinessFunction)', 'Client (type: BusinessActor) AssignmentRelationship Information Provisioning (type: BusinessFunction)', 'Front Office (type: BusinessActor) AssignmentRelationship Customer Relations (type: BusinessFunction)', 'Front Office (type: BusinessActor) AssignmentRelationship Marketing (type: BusinessFunction)', 'Front Office (type: BusinessActor) AssignmentRelationship Sales (type: BusinessFunction)', 'Shared Service Center (type: BusinessActor) AssignmentRelationship Document Processing (type: BusinessFunction)'] | G2: ['ArchiSurance (type: BusinessActor)', 'Front Office (type: BusinessActor)', 'Back Office (type: BusinessActor)', 'Shared Service Center (type: BusinessActor)', "Homeowner's Travel Back Office (type: BusinessActor)", 'Legal Expense Back Office (type: BusinessActor)', 'Auto Back Office (type: BusinessActor)', 'Client (type: BusinessActor)', 'Bank (type: BusinessActor)', 'Customer Service (type: BusinessActor)', 'Business Intelligence Team (type: BusinessActor)'] | H2: ['With the orgnaization ArchiSurance (a Business Actor) is responsible for carring out functions', 'With the orgnaization Front Office (a Business Actor) is responsible for carring out functions', 'With the orgnaization Back Office (a Business Actor) is responsible for carring out functions', 'With the orgnaization Shared Service Center (a Business Actor) is responsible for carring out functions', "With the orgnaization Homeowner's Travel Back Office (a Business Actor) is responsible for carring out functions", 'With the orgnaization Legal Expense Back Office (a Business Actor) is responsible for carring out functions', 'With the orgnaization Auto Back Office (a Business Actor) is responsible for carring out functions', 'With the orgnaization Client (a Business Actor) is responsible for carring out functions', 'With the orgnaization Bank (a Business Actor) is responsible for carring out functions', 'With the orgnaization Customer Service (a Business Actor) is responsible for carring out functions', 'With the orgnaization Business Intelligence Team (a Business Actor) is responsible for carring out functions'] | I2: ['Back Office (type: BusinessActor) AssignmentRelationship Actuarial (type: BusinessFunction)', 'Back Office (type: BusinessActor) AssignmentRelationship Claims (type: BusinessFunction)', 'Back Office (type: BusinessActor) AssignmentRelationship Finance (type: BusinessFunction)', 'Back Office (type: BusinessActor) AssignmentRelationship Investment Management (type: BusinessFunction)', 'Back Office (type: BusinessActor) AssignmentRelationship Underwriting (type: BusinessFunction)', 'Bank (type: BusinessActor) AssignmentRelationship Banking (type: BusinessFunction)', 'Client (type: BusinessActor) AssignmentRelationship Buying Insurance (type: BusinessFunction)', 'Client (type: BusinessActor) AssignmentRelationship Claims Submission (type: BusinessFunction)', 'Client (type: BusinessActor) AssignmentRelationship Information Provisioning (type: BusinessFunction)', 'Front Office (type: BusinessActor) AssignmentRelationship Customer Relations (type: BusinessFunction)', 'Front Office (type: BusinessActor) AssignmentRelationship Marketing (type: BusinessFunction)', 'Front Office (type: BusinessActor) AssignmentRelationship Sales (type: BusinessFunction)', 'Shared Service Center (type: BusinessActor) AssignmentRelationship Document Processing (type: BusinessFunction)'] | J2: ['With the orgnaization ArchiSurance (a Business Actor) is responsible for carring out functions', 'With the orgnaization Front Office (a Business Actor) is responsible for carring out functions', 'With the orgnaization Back Office (a Business Actor) is responsible for carring out functions', 'With the orgnaization Shared Service Center (a Business Actor) is responsible for carring out functions', "With the orgnaization Homeowner's Travel Back Office (a Business Actor) is responsible for carring out functions", 'With the orgnaization Legal Expense Back Office (a Business Actor) is responsible for carring out functions', 'With the orgnaization Auto Back Office (a Business Actor) is responsible for carring out functions', 'With the orgnaization Client (a Business Actor) is responsible for carring out functions', 'With the orgnaization Bank (a Business Actor) is responsible for carring out functions', 'With the orgnaization Customer Service (a Business Actor) is responsible for carring out functions', 'With the orgnaization Business Intelligence Team (a Business Actor) is responsible for carring out functions'] | K2: ['back office (type: businessactor) assignmentrelationship actuarial (type:businessfunction)', 'back office (type: businessactor) assignmentrelationship claims (type:businessfunction)', 'back office (type: businessactor) assignmentrelationship finance (type:businessfunction)', 'back office (type: businessactor) assignmentrelationship investment management (type:businessfunction)', 'back office (type: businessactor) assignmentrelationship underwriting (type:businessfunction)', 'bank (type: businessactor) assignmentrelationship banking (type:businessfunction)', 'client (type: businessactor) assignmentrelationship buying insurance (type:businessfunction)', 'client (type: businessactor) assignmentrelationship claims submission (type:businessfunction)', 'client (type: businessactor) assignmentrelationship information provisioning (type:businessfunction)', 'front office (type: businessactor) assignmentrelationship customer relations (type:businessfunction)', 'front office (type: businessactor) assignmentrelationship marketing (type:businessfunction)', 'front office (type: businessactor) assignmentrelationship sales (type:businessfunction)', 'shared service center (type: businessactor) assignmentrelationship document processing (type:businessfunction)'] | L2: ['back office (type: businessactor) assignmentrelationship actuarial (type:businessfunction)', 'back office (type: businessactor) assignmentrelationship claims (type:businessfunction)', 'back office (type: businessactor) assignmentrelationship finance (type:businessfunction)', 'back office (type: businessactor) assignmentrelationship investment management (type:businessfunction)', 'back office (type: businessactor) assignmentrelationship underwriting (type:businessfunction)', 'bank (type: businessactor) assignmentrelationship banking (type:businessfunction)', 'client (type: businessactor) assignmentrelationship buying insurance (type:businessfunction)', 'client (type: businessactor) assignmentrelationship claims submission (type:businessfunction)', 'client (type: businessactor) assignmentrelationship information provisioning (type:businessfunction)', 'front office (type: businessactor) assignmentrelationship customer relations (type:businessfunction)', 'front office (type: businessactor) assignmentrelationship marketing (type:businessfunction)', 'front office (type: businessactor) assignmentrelationship sales (type:businessfunction)', 'shared service center (type: businessactor) assignmentrelationship document processing (type:businessfunction)'] | M2: ['archisurance (type:businessactor)', 'front office (type:businessactor)', 'back office (type:businessactor)', 'shared service center (type:businessactor)', "homeowner's travel back office (type:businessactor)", 'legal expense back office (type:businessactor)', 'auto back office (type:businessactor)', 'client (type:businessactor)', 'bank (type:businessactor)', 'customer service (type:businessactor)', 'business intelligence team (type:businessactor)'] | N2: 1 | O2: 0 | P2: 0 | Q2: 0 | R2: 0.80385478 | S2: 0 | T2: 0.73888305 | U2: 0.27777778
A3: Entity Only | B3: What are the devices used? | C3: The devices used are: ArchiSurance General-Purpose Back-Up Server Cluster (type: Device), ArchiSurance General-Purpose Server Cluster (type: Device), Auto General-Purpose Server (type: Device), Document Management Back-Up Server (type: Device), Document Management Server (type: Device), FO General-Purpose Server (type: Device), FO Web Hosting Server (type: Device), and Legal Expense General-Purpose Server (type: Device). | D3: The organization consists of the following devices ArchiSurance General-Purpose Server Cluster (type: Device), FO General-Purpose Server (type: Device), FO Web Hosting Server (type: Device), Legal Expense General-Purpose Server (type: Device), Document Management Server (type: Device), Auto General-Purpose Server (type: Device), Document Management Back-Up Server (type: Device), and ArchiSurance General-Purpose Back-Up Server Cluster (type: Device). | E3: ['ArchiSurance General-Purpose Back-Up Server Cluster (type: Device)', 'ArchiSurance General-Purpose Server Cluster (type: Device)', 'Auto General-Purpose Server (type: Device)', 'Document Management Back-Up Server (type: Device)', 'Document Management Server (type: Device)', 'FO General-Purpose Server (type: Device)', 'FO Web Hosting Server (type: Device)', 'Legal Expense General-Purpose Server (type: Device)'] | F3: ['ArchiSurance General-Purpose Back-Up Server Cluster (type: Device)', 'ArchiSurance General-Purpose Server Cluster (type: Device)', 'Auto General-Purpose Server (type: Device)', 'Document Management Back-Up Server (type: Device)', 'Document Management Server (type: Device)', 'FO General-Purpose Server (type: Device)', 'FO Web Hosting Server (type: Device)', 'Legal Expense General-Purpose Server (type: Device)'] | G3: ['ArchiSurance General-Purpose Server Cluster (type: Device)', 'FO General-Purpose Server (type: Device)', 'FO Web Hosting Server (type: Device)', 'Legal Expense General-Purpose Server (type: Device)', 'Document Management Server (type: Device)', 'Auto General-Purpose Server (type: Device)', 'Document Management Back-Up Server (type: Device)', 'ArchiSurance General-Purpose Back-Up Server Cluster (type: Device)'] | H3: ['The domain consists of the followng devices ArchiSurance General-Purpose Server Cluster, FO General-Purpose Server, FO Web Hosting Server, Legal Expense General-Purpose Server, Document Management Server, Auto General-Purpose Server, Document Management Back-Up Server, and ArchiSurance General-Purpose Back-Up Server Cluster.'] | I3: ['ArchiSurance General-Purpose Back-Up Server Cluster (type: Device)', 'ArchiSurance General-Purpose Server Cluster (type: Device)', 'Auto General-Purpose Server (type: Device)', 'Document Management Back-Up Server (type: Device)', 'Document Management Server (type: Device)', 'FO General-Purpose Server (type: Device)', 'FO Web Hosting Server (type: Device)', 'Legal Expense General-Purpose Server (type: Device)'] | J3: ['The domain consists of the followng devices ArchiSurance General-Purpose Server Cluster, FO General-Purpose Server, FO Web Hosting Server, Legal Expense General-Purpose Server, Document Management Server, Auto General-Purpose Server, Document Management Back-Up Server, and ArchiSurance General-Purpose Back-Up Server Cluster.'] | K3: ['archisurance general-purpose back-up server cluster (type:device)', 'archisurance general-purpose server cluster (type:device)', 'auto general-purpose server (type:device)', 'document management back-up server (type:device)', 'document management server (type:device)', 'fo general-purpose server (type:device)', 'fo web hosting server (type:device)', 'legal expense general-purpose server (type:device)'] | L3: ['archisurance general-purpose back-up server cluster (type:device)', 'archisurance general-purpose server cluster (type:device)', 'auto general-purpose server (type:device)', 'document management back-up server (type:device)', 'document management server (type:device)', 'fo general-purpose server (type:device)', 'fo web hosting server (type:device)', 'legal expense general-purpose server (type:device)'] | M3: ['archisurance general-purpose server cluster (type:device)', 'fo general-purpose server (type:device)', 'fo web hosting server (type:device)', 'legal expense general-purpose server (type:device)', 'document management server (type:device)', 'auto general-purpose server (type:device)', 'document management back-up server (type:device)', 'archisurance general-purpose back-up server cluster (type:device)'] | N3: 1 | O3: 1 | P3: 1 | Q3: 1 | R3: 0.90637028 | S3: 1 | T3: 0.91513299 | U3: 1
A4: Entity Only | B4: What are the services that are carried out by software? | C4: The services carried out by software include the following application services: Claims Administration (type: ApplicationService), CRM Data Access (type: ApplicationService), Customer Administration (type: ApplicationService), Financial Service (type: ApplicationService), Payment (type: ApplicationService), Policy Administration Service (type: ApplicationService), Printing (type: ApplicationService), and Scanning (type: ApplicationService). | D4: The services carried out by software/applicatons are Scanning (type: ApplicationService), Customer Administration (type: ApplicationService), Claims Administration (type: ApplicationService), Printing (type: ApplicationService), Payment (type: ApplicationService), Policy Administration Service (type: ApplicationService), Financial Service (type: ApplicationService), and CRM Data Access (type: ApplicationService) | E4: ['Claims Administration (type: ApplicationService)', 'CRM Data Access (type: ApplicationService)', 'Customer Administration (type: ApplicationService)', 'Device Operation Service (type: TechnologyService)', 'Device Registration Service (type: TechnologyService)', 'Financial Service (type: ApplicationService)', 'Notification Service (type: TechnologyService)', 'PaaS Service (type: TechnologyService)', 'Payment (type: ApplicationService)', 'Policy Administration Service (type: ApplicationService)', 'Printing (type: ApplicationService)', 'Scanning (type: ApplicationService)'] | F4: ['Claims Administration (type: ApplicationService)', 'CRM Data Access (type: ApplicationService)', 'Customer Administration (type: ApplicationService)', 'Financial Service (type: ApplicationService)', 'Payment (type: ApplicationService)', 'Policy Administration Service (type: ApplicationService)', 'Printing (type: ApplicationService)', 'Scanning (type: ApplicationService)'] | G4: ['Scanning (type: ApplicationService)', 'Customer Administration (type: ApplicationService)', 'Claims Administration (type: ApplicationService)', 'Printing (type: ApplicationService)', 'Payment (type: ApplicationService)', 'Policy Administration Service (type: ApplicationService)', 'Financial Service (type: ApplicationService)', 'CRM Data Access (type: ApplicationService)'] | H4: ['The services carried out by software/applicatons are Scanning, Customer Administration, Claims Administration, Printing, Payment, Policy Administration Service, Financial Service, and CRM Data Access.'] | I4: ['Claims Administration (type: ApplicationService)', 'CRM Data Access (type: ApplicationService)', 'Customer Administration (type: ApplicationService)', 'Device Operation Service (type: TechnologyService)', 'Device Registration Service (type: TechnologyService)', 'Financial Service (type: ApplicationService)', 'Notification Service (type: TechnologyService)', 'PaaS Service (type: TechnologyService)', 'Payment (type: ApplicationService)', 'Policy Administration Service (type: ApplicationService)', 'Printing (type: ApplicationService)', 'Scanning (type: ApplicationService)'] | J4: ['The services carried out by software/applicatons are Scanning, Customer Administration, Claims Administration, Printing, Payment, Policy Administration Service, Financial Service, and CRM Data Access.'] | K4: ['claims administration (type:applicationservice)', 'crm data access (type:applicationservice)', 'customer administration (type:applicationservice)', 'device operation service (type:technologyservice)', 'device registration service (type:technologyservice)', 'financial service (type:applicationservice)', 'notification service (type:technologyservice)', 'paas service (type:technologyservice)', 'payment (type:applicationservice)', 'policy administration service (type:applicationservice)', 'printing (type:applicationservice)', 'scanning (type:applicationservice)'] | L4: ['claims administration (type:applicationservice)', 'crm data access (type:applicationservice)', 'customer administration (type:applicationservice)', 'financial service (type:applicationservice)', 'payment (type:applicationservice)', 'policy administration service (type:applicationservice)', 'printing (type:applicationservice)', 'scanning (type:applicationservice)'] | M4: ['scanning (type:applicationservice)', 'customer administration (type:applicationservice)', 'claims administration (type:applicationservice)', 'printing (type:applicationservice)', 'payment (type:applicationservice)', 'policy administration service (type:applicationservice)', 'financial service (type:applicationservice)', 'crm data access (type:applicationservice)'] | N4: 0.66666667 | O4: 1 | P4: 1 | Q4: 1 | R4: 0.84052802 | S4: 1 | T4: 0.92844979 | U4: 1
A5: Entity Only | B5: What are the resources have been defined? | C5: The defined resources are Data Analysis Automation (type: Resource), Data Sources (type: Resource), Enterprise-Wide CRM Automation (type: Resource), Integrated Back Office Automation (type: Resource), Social Media Apps (type: Resource), Staff with Data Analysis Competency (type: Resource), and Staff with Social Media Competency (type: Resource). | D5: The resources defined are Enterprise-Wide CRM Automation (type: Resource), Integrated Back Office Automation (type: Resource), Social Media Apps (type: Resource), Staff with Social Media Competency (type: Resource), Data Analysis Automation (type: Resource), Data Sources (type: Resource), Staff with Data Analysis Competency (type: Resource) | E5: ['Data Analysis Automation (type: Resource)', 'Data Sources (type: Resource)', 'Enterprise-Wide CRM Automation (type: Resource)', 'Integrated Back Office Automation (type: Resource)', 'Social Media Apps (type: Resource)', 'Staff with Data Analysis Competency (type: Resource)', 'Staff with Social Media Competency (type: Resource)'] | F5: ['Data Analysis Automation (type: Resource)', 'Data Sources (type: Resource)', 'Enterprise-Wide CRM Automation (type: Resource)', 'Integrated Back Office Automation (type: Resource)', 'Social Media Apps (type: Resource)', 'Staff with Data Analysis Competency (type: Resource)', 'Staff with Social Media Competency (type: Resource)'] | G5: ['Enterprise-Wide CRM Automation (type: Resource)', 'Integrated Back Office Automation (type: Resource)', 'Social Media Apps (type: Resource)', 'Staff with Social Media Competency (type: Resource)', 'Data Analysis Automation (type: Resource)', 'Data Sources (type: Resource)', 'Staff with Data Analysis Competency (type: Resource)'] | H5: ['The resources within the domain are Enterprise-Wide CRM Automation, Integrated Back Office Automation, Social Media Apps, Staff with Social Media Competency, Data Analysis Automation, Data Sources, Staff with Data Analysis Competency.'] | I5: ['Data Analysis Automation (type: Resource)', 'Data Sources (type: Resource)', 'Enterprise-Wide CRM Automation (type: Resource)', 'Integrated Back Office Automation (type: Resource)', 'Social Media Apps (type: Resource)', 'Staff with Data Analysis Competency (type: Resource)', 'Staff with Social Media Competency (type: Resource)'] | J5: ['The resources within the domain are Enterprise-Wide CRM Automation, Integrated Back Office Automation, Social Media Apps, Staff with Social Media Competency, Data Analysis Automation, Data Sources, Staff with Data Analysis Competency.'] | K5: ['data analysis automation (type:resource)', 'data sources (type:resource)', 'enterprise-wide crm automation (type:resource)', 'integrated back office automation (type:resource)', 'social media apps (type:resource)', 'staff with data analysis competency (type:resource)', 'staff with social media competency (type:resource)'] | L5: ['data analysis automation (type:resource)', 'data sources (type:resource)', 'enterprise-wide crm automation (type:resource)', 'integrated back office automation (type:resource)', 'social media apps (type:resource)', 'staff with data analysis competency (type:resource)', 'staff with social media competency (type:resource)'] | M5: ['enterprise-wide crm automation (type:resource)', 'integrated back office automation (type:resource)', 'social media apps (type:resource)', 'staff with social media competency (type:resource)', 'data analysis automation (type:resource)', 'data sources (type:resource)', 'staff with data analysis competency (type:resource)'] | N5: 1 | O5: 1 | P5: 1 | Q5: 1 | R5: 0.90687339 | S5: 1 | T5: 0.92802701 | U5: 1
A6: Entity Only | B6: What is the name of the organization that is represented in the model? | C6: The organization represented in the model is ArchiSurance (type: BusinessActor). | D6: The organization represented in the model is ArchiSurance (type: BusinessActor). | E6: ['ArchiSurance (type: BusinessActor)', 'ArchiSurance (type: Location)'] | F6: ['ArchiSurance (type: BusinessActor)'] | G6: ['ArchiSurance (type: BusinessActor)'] | H6: ['Archisurance is name of the organization represented in the model.'] | I6: ['ArchiSurance (type: BusinessActor)', 'ArchiSurance (type: Location)'] | J6: ['Archisurance is name of the organization represented in the model.'] | K6: ['archisurance (type:businessactor)', 'archisurance (type:location)'] | L6: ['archisurance (type:businessactor)'] | M6: ['archisurance (type:businessactor)'] | N6: 0.5 | O6: 1 | P6: 1 | Q6: 1 | R6: 0.92162995 | S6: 1 | T6: 1 | U6: 0.5
A7: Entity Only | B7: Does the organization defined in the model have a mobile app? | C7: Yes—the model includes a mobile application named MyArchiSurance Mobile App (type: ApplicationComponent). | D7: Yes ArchiSurance (type: BusinessActor) has a the MyArchiSurance Mobile App (type: ApplicationComponent). | E7: ['ArchiSurance Back Office Suite (type: ApplicationComponent)', 'Auto Insurance Application (type: ApplicationComponent)', 'AUTO-U (type: ApplicationComponent)', 'BRIMS (type: ApplicationComponent)', 'Call Center Application (type: ApplicationComponent)', 'Document Management System (type: ApplicationComponent)', 'General CRM System (type: ApplicationComponent)', 'Home & Away Financial Application (type: ApplicationComponent)', 'Home & Away Policy Administration (type: ApplicationComponent)', 'Legal Expense Back-Office System (type: ApplicationComponent)', 'Legal Expense CRM System (type: ApplicationComponent)', 'MyArchiSurance Mobile App (type: ApplicationComponent)', 'P-ADMIN (type: ApplicationComponent)', 'P-CONFIG (type: ApplicationComponent)', 'VERSA-CLAIM (type: ApplicationComponent)', 'Web Portal (type: ApplicationComponent)'] | F7: ['MyArchiSurance Mobile App (type: ApplicationComponent)'] | G7: ['ArchiSurance (type: BusinessActor)', 'MyArchiSurance Mobile App (type: ApplicationComponent)'] | H7: ['ArchiSurance has a mobile app called MyArchiSurance Mobile App.'] | I7: ['ArchiSurance Back Office Suite (type: ApplicationComponent)', 'Auto Insurance Application (type: ApplicationComponent)', 'AUTO-U (type: ApplicationComponent)', 'BRIMS (type: ApplicationComponent)', 'Call Center Application (type: ApplicationComponent)', 'Document Management System (type: ApplicationComponent)', 'General CRM System (type: ApplicationComponent)', 'Home & Away Financial Application (type: ApplicationComponent)', 'Home & Away Policy Administration (type: ApplicationComponent)', 'Legal Expense Back-Office System (type: ApplicationComponent)', 'Legal Expense CRM System (type: ApplicationComponent)', 'MyArchiSurance Mobile App (type: ApplicationComponent)', 'P-ADMIN (type: ApplicationComponent)', 'P-CONFIG (type: ApplicationComponent)', 'VERSA-CLAIM (type: ApplicationComponent)', 'Web Portal (type: ApplicationComponent)'] | J7: ['ArchiSurance has a mobile app called MyArchiSurance Mobile App.'] | K7: ['archisurance back office suite (type:applicationcomponent)', 'auto insurance application (type:applicationcomponent)', 'auto-u (type:applicationcomponent)', 'brims (type:applicationcomponent)', 'call center application (type:applicationcomponent)', 'document management system (type:applicationcomponent)', 'general crm system (type:applicationcomponent)', 'home and away financial application (type:applicationcomponent)', 'home and away policy administration (type:applicationcomponent)', 'legal expense back-office system (type:applicationcomponent)', 'legal expense crm system (type:applicationcomponent)', 'myarchisurance mobile app (type:applicationcomponent)', 'p-admin (type:applicationcomponent)', 'p-config (type:applicationcomponent)', 'versa-claim (type:applicationcomponent)', 'web portal (type:applicationcomponent)'] | L7: ['myarchisurance mobile app (type:applicationcomponent)'] | M7: ['archisurance (type:businessactor)', 'myarchisurance mobile app (type:applicationcomponent)'] | N7: 0.0625 | O7: 1 | P7: 0.5 | Q7: 0.66666667 | R7: 0.75485472 | S7: 0.67 | T7: 0.81440107 | U7: 0.5
A8: Entity Only | B8: What are the software interfaces within this domain? | C8: The software interface within this domain is REST API (type: TechnologyInterface). | D8: REST API (type: TechnologyInterface) is defined as a software interface. | E8: ['Claims Administration (type: ApplicationService)', 'CRM Data Access (type: ApplicationService)', 'Customer Administration (type: ApplicationService)', 'Financial Service (type: ApplicationService)', 'Payment (type: ApplicationService)', 'Policy Administration Service (type: ApplicationService)', 'Printing (type: ApplicationService)', 'REST API (type: TechnologyInterface)', 'Scanning (type: ApplicationService)'] | F8: ['REST API (type: TechnologyInterface)'] | G8: ['REST API (type: TechnologyInterface)'] | H8: ['REST API is a technology interface that acts as a software interface.'] | I8: ['Claims Administration (type: ApplicationService)', 'CRM Data Access (type: ApplicationService)', 'Customer Administration (type: ApplicationService)', 'Financial Service (type: ApplicationService)', 'Payment (type: ApplicationService)', 'Policy Administration Service (type: ApplicationService)', 'Printing (type: ApplicationService)', 'REST API (type: TechnologyInterface)', 'Scanning (type: ApplicationService)'] | J8: ['REST API is a technology interface that acts as a software interface.'] | K8: ['claims administration (type:applicationservice)', 'crm data access (type:applicationservice)', 'customer administration (type:applicationservice)', 'financial service (type:applicationservice)', 'payment (type:applicationservice)', 'policy administration service (type:applicationservice)', 'printing (type:applicationservice)', 'rest api (type:technologyinterface)', 'scanning (type:applicationservice)'] | L8: ['rest api (type:technologyinterface)'] | M8: ['rest api (type:technologyinterface)'] | N8: 0.11111111 | O8: 1 | P8: 1 | Q8: 1 | R8: 0.94322536 | S8: 1 | T8: 0.71843501 | U8: 1
A9: Entity Only | B9: What automation resources does the organization have? | C9: The organization’s automation resources include Data Analysis Automation (type: Resource), Enterprise-Wide CRM Automation (type: Resource), and Integrated Back Office Automation (type: Resource). | D9: The organization has implemented automation in the form of Enterprise-Wide CRM Automation (type: Resource), Data Analysis Automation (type: Resource), and Integrated Back Office Automation (type: Resource). | E9: ['ArchiSurance Back Office Suite (type: ApplicationComponent)', 'ArchiSurance General-Purpose Back-Up Server Cluster (type: Device)', 'ArchiSurance General-Purpose Server Cluster (type: Device)', 'Call Center Application (type: ApplicationComponent)', 'Container (type: SystemSoftware)', 'Data Acquisition (type: Capability)', 'Data Acquisition (type: TechnologyFunction)', 'Data Acquisition Gateway (type: Node)', 'Data Analysis (type: Capability)', 'Data Analysis Automation (type: Resource)', 'Data Sources (type: Resource)', 'Data Warehousing Solution (type: ApplicationComponent)', 'Document Management Back-Up Server (type: Device)', 'Document Management Server (type: Device)', 'Document Management System (type: ApplicationComponent)', 'Enterprise-Wide CRM Automation (type: Resource)', 'General CRM System (type: ApplicationComponent)', 'Integrated Back Office Automation (type: Resource)', 'IT Management (type: Capability)', 'Notification Service (type: TechnologyService)', 'PaaS Service (type: TechnologyService)', 'Process Management (type: Capability)', 'REST API (type: TechnologyInterface)', 'Social Media Apps (type: Resource)', 'Staff with Data Analysis Competency (type: Resource)', 'Staff with Social Media Competency (type: Resource)'] | F9: ['Data Analysis Automation (type: Resource)', 'Enterprise-Wide CRM Automation (type: Resource)', 'Integrated Back Office Automation (type: Resource)'] | G9: ['Enterprise-Wide CRM Automation (type: Resource)', 'Data Analysis Automation (type: Resource)', 'Integrated Back Office Automation (type: Resource)'] | H9: ['The organization has automation in the form of Enterprise-Wide CRM Automation, Data Analysis Automation, and Integrated Back Office Automation'] | I9: ['ArchiSurance Back Office Suite (type: ApplicationComponent)', 'ArchiSurance General-Purpose Back-Up Server Cluster (type: Device)', 'ArchiSurance General-Purpose Server Cluster (type: Device)', 'Call Center Application (type: ApplicationComponent)', 'Container (type: SystemSoftware)', 'Data Acquisition (type: Capability)', 'Data Acquisition (type: TechnologyFunction)', 'Data Acquisition Gateway (type: Node)', 'Data Analysis (type: Capability)', 'Data Analysis Automation (type: Resource)', 'Data Sources (type: Resource)', 'Data Warehousing Solution (type: ApplicationComponent)', 'Document Management Back-Up Server (type: Device)', 'Document Management Server (type: Device)', 'Document Management System (type: ApplicationComponent)', 'Enterprise-Wide CRM Automation (type: Resource)', 'General CRM System (type: ApplicationComponent)', 'Integrated Back Office Automation (type: Resource)', 'IT Management (type: Capability)', 'Notification Service (type: TechnologyService)', 'PaaS Service (type: TechnologyService)', 'Process Management (type: Capability)', 'REST API (type: TechnologyInterface)', 'Social Media Apps (type: Resource)', 'Staff with Data Analysis Competency (type: Resource)', 'Staff with Social Media Competency (type: Resource)'] | J9: ['The organization has automation in the form of Enterprise-Wide CRM Automation, Data Analysis Automation, and Integrated Back Office Automation'] | K9: ['archisurance back office suite (type:applicationcomponent)', 'archisurance general-purpose back-up server cluster (type:device)', 'archisurance general-purpose server cluster (type:device)', 'call center application (type:applicationcomponent)', 'container (type:systemsoftware)', 'data acquisition (type:capability)', 'data acquisition (type:technologyfunction)', 'data acquisition gateway (type:node)', 'data analysis (type:capability)', 'data analysis automation (type:resource)', 'data sources (type:resource)', 'data warehousing solution (type:applicationcomponent)', 'document management back-up server (type:device)', 'document management server (type:device)', 'document management system (type:applicationcomponent)', 'enterprise-wide crm automation (type:resource)', 'general crm system (type:applicationcomponent)', 'integrated back office automation (type:resource)', 'it management (type:capability)', 'notification service (type:technologyservice)', 'paas service (type:technologyservice)', 'process management (type:capability)', 'rest api (type:technologyinterface)', 'social media apps (type:resource)', 'staff with data analysis competency (type:resource)', 'staff with social media competency (type:resource)'] | L9: ['data analysis automation (type:resource)', 'enterprise-wide crm automation (type:resource)', 'integrated back office automation (type:resource)'] | M9: ['enterprise-wide crm automation (type:resource)', 'data analysis automation (type:resource)', 'integrated back office automation (type:resource)'] | N9: 0.11538462 | O9: 1 | P9: 1 | Q9: 1 | R9: 0.99999938 | S9: 1 | T9: 0.90408497 | U9: 1
A10: Relation Only | B10: What are the specializations between entities that are present within the domain? | C10: The domain includes the following specializations: Auto Insurance Policy (type: BusinessObject) specializes Insurance Policy (type: BusinessObject); Homeowner's Insurance Policy (type: BusinessObject) specializes Insurance Policy (type: BusinessObject); Legal Expense Insurance Policy (type: BusinessObject) specializes Insurance Policy (type: BusinessObject); Travel Insurance Policy (type: BusinessObject) specializes Insurance Policy (type: BusinessObject); and Car Black Box (type: Equipment), Fitness Tracker (type: Equipment), Home Alarm System (type: Equipment), and Smart Thermostat (type: Equipment) each specialize IoT Devices (type: Equipment). | D10: In the model Travel Insurance Policy (type: BusinessObject), Homeowner Insurance Policy (type: BusinessObject), Auto Insurance Policy (type: BusinessObject), and Legal Insurance Policy (type: BusinessObject) are specializations of the Insurance Policy (type: BusinessObject), while Car Black Box (type: Equipment), Fitness Tracker (type: Equipment), Home Alarm (type: Equipment), and Smart Thermostat (type: Equipment) are specializations of IoT Device (type: Equipment). | E10: ['Auto Insurance Policy (type: BusinessObject) SpecializationRelationship Insurance Policy (type: BusinessObject)', 'Car Black Box (type: Equipment) SpecializationRelationship IoT Devices (type: Equipment)', 'Fitness Tracker (type: Equipment) SpecializationRelationship IoT Devices (type: Equipment)', 'Home Alarm System (type: Equipment) SpecializationRelationship IoT Devices (type: Equipment)', "Homeowner's Insurance Policy (type: BusinessObject) SpecializationRelationship Insurance Policy (type: BusinessObject)", 'Legal Expense Insurance Policy (type: BusinessObject) SpecializationRelationship Insurance Policy (type: BusinessObject)', 'Smart Thermostat (type: Equipment) SpecializationRelationship IoT Devices (type: Equipment)', 'Travel Insurance Policy (type: BusinessObject) SpecializationRelationship Insurance Policy (type: BusinessObject)'] | F10: ['Auto Insurance Policy (type: BusinessObject) SpecializationRelationship Insurance Policy (type: BusinessObject)', "Homeowner's Insurance Policy (type: BusinessObject) SpecializationRelationship Insurance Policy (type: BusinessObject)", 'Legal Expense Insurance Policy (type: BusinessObject) SpecializationRelationship Insurance Policy (type: BusinessObject)', 'Travel Insurance Policy (type: BusinessObject) SpecializationRelationship Insurance Policy (type: BusinessObject)', 'Car Black Box (type: Equipment) SpecializationRelationship IoT Devices (type: Equipment)', 'Fitness Tracker (type: Equipment) SpecializationRelationship IoT Devices (type: Equipment)', 'Home Alarm System (type: Equipment) SpecializationRelationship IoT Devices (type: Equipment)', 'Smart Thermostat (type: Equipment) SpecializationRelationship IoT Devices (type: Equipment)'] | G10: ['Travel Insurance Policy (type: BusinessObject) SpecializationRelationship Insurance Policy (type: BusinessObject)', "Homeowner's Insurance Policy (type: BusinessObject) SpecializationRelationship Insurance Policy (type: BusinessObject)", 'Auto Insurance Policy (type: BusinessObject) SpecializationRelationship Insurance Policy (type: BusinessObject)', 'Legal Insurance Policy (type: BusinessObject) SpecializationRelationship Insurance Policy (type: BusinessObject)', 'Car Black Box (type: Equipment) SpecializationRelationship IoT Devices (type: Equipment)', 'Fitness Tracker (type: Equipment) SpecializationRelationship IoT Devices (type: Equipment)', 'Home Alarm (type: Equipment) SpecializationRelationship IoT Devices (type: Equipment)', 'Smart Thermostat (type: Equipment) SpecializationRelationship IoT Devices (type: Equipment)'] | H10: ['Travel Insurance Policy (a business object) is a specialization of Insurance Policy (a business object).', "Homeowner's Insurance Policy (a business object) is a specialization of Insurance Policy (a business object).", 'Auto Insurance Policy (a business object) is a specialization of Insurance Policy (a business object).', 'Legal Insurance Policy (a business object) is a specialization of Insurance Policy (a business object).', 'Car Black Box (an equipment) is a specialization of IoT Devices (an equipment).', 'Fitness Tracker (an equipment) is a specialization of IoT Devices (an equipment).', 'Home Alarm (an equipment) is a specialization of IoT Devices (an equipment).', 'Smart Thermostat (an equipment) is a specialization of IoT Devices (an equipment).'] | I10: ['Auto Insurance Policy (type: BusinessObject) SpecializationRelationship Insurance Policy (type: BusinessObject)', 'Car Black Box (type: Equipment) SpecializationRelationship IoT Devices (type: Equipment)', 'Fitness Tracker (type: Equipment) SpecializationRelationship IoT Devices (type: Equipment)', 'Home Alarm System (type: Equipment) SpecializationRelationship IoT Devices (type: Equipment)', "Homeowner's Insurance Policy (type: BusinessObject) SpecializationRelationship Insurance Policy (type: BusinessObject)", 'Legal Expense Insurance Policy (type: BusinessObject) SpecializationRelationship Insurance Policy (type: BusinessObject)', 'Smart Thermostat (type: Equipment) SpecializationRelationship IoT Devices (type: Equipment)', 'Travel Insurance Policy (type: BusinessObject) SpecializationRelationship Insurance Policy (type: BusinessObject)'] | J10: ['Travel Insurance Policy (a business object) is a specialization of Insurance Policy (a business object).', "Homeowner's Insurance Policy (a business object) is a specialization of Insurance Policy (a business object).", 'Auto Insurance Policy (a business object) is a specialization of Insurance Policy (a business object).', 'Legal Insurance Policy (a business object) is a specialization of Insurance Policy (a business object).', 'Car Black Box (an equipment) is a specialization of IoT Devices (an equipment).', 'Fitness Tracker (an equipment) is a specialization of IoT Devices (an equipment).', 'Home Alarm (an equipment) is a specialization of IoT Devices (an equipment).', 'Smart Thermostat (an equipment) is a specialization of IoT Devices (an equipment).'] | K10: ['auto insurance policy (type: businessobject) specializationrelationship insurance policy (type:businessobject)', 'car black box (type: equipment) specializationrelationship iot devices (type:equipment)', 'fitness tracker (type: equipment) specializationrelationship iot devices (type:equipment)', 'home alarm system (type: equipment) specializationrelationship iot devices (type:equipment)', "homeowner's insurance policy (type: businessobject) specializationrelationship insurance policy (type:businessobject)", 'legal expense insurance policy (type: businessobject) specializationrelationship insurance policy (type:businessobject)', 'smart thermostat (type: equipment) specializationrelationship iot devices (type:equipment)', 'travel insurance policy (type: businessobject) specializationrelationship insurance policy (type:businessobject)'] | L10: ['auto insurance policy (type: businessobject) specializationrelationship insurance policy (type:businessobject)', "homeowner's insurance policy (type: businessobject) specializationrelationship insurance policy (type:businessobject)", 'legal expense insurance policy (type: businessobject) specializationrelationship insurance policy (type:businessobject)', 'travel insurance policy (type: businessobject) specializationrelationship insurance policy (type:businessobject)', 'car black box (type: equipment) specializationrelationship iot devices (type:equipment)', 'fitness tracker (type: equipment) specializationrelationship iot devices (type:equipment)', 'home alarm system (type: equipment) specializationrelationship iot devices (type:equipment)', 'smart thermostat (type: equipment) specializationrelationship iot devices (type:equipment)'] | M10: ['travel insurance policy (type: businessobject) specializationrelationship insurance policy (type:businessobject)', "homeowner's insurance policy (type: businessobject) specializationrelationship insurance policy (type:businessobject)", 'auto insurance policy (type: businessobject) specializationrelationship insurance policy (type:businessobject)', 'legal insurance policy (type: businessobject) specializationrelationship insurance policy (type:businessobject)', 'car black box (type: equipment) specializationrelationship iot devices (type:equipment)', 'fitness tracker (type: equipment) specializationrelationship iot devices (type:equipment)', 'home alarm (type: equipment) specializationrelationship iot devices (type:equipment)', 'smart thermostat (type: equipment) specializationrelationship iot devices (type:equipment)'] | N10: 1 | O10: 0.75 | P10: 0.75 | Q10: 0.75 | R10: 0.74319121 | S10: 1 | T10: 0.88350849 | U10: 0.75
